Workbook

Sheet Bond Toolkit
A1: Interest Rate / Bond Cash-Flow Toolkit
A2: Blue = inputs. Black = formulas. Change inputs → outputs/cash-flows update. Use 'Run Scenarios' VBA to fill scenario table.
A4: INPUTS
A5: Face Value (FV) | B5: 1000 | D5: Max rows in CF table | E5: 200
A6: Annual Coupon Rate (c) | B6: 0.05 | D6: DERIVED (do not edit)
A7: Maturity (years, T) | B7: 10 | D7: Coupon per period | E7: =B5*B6/B8
A8: Coupon Frequency (p payments/year) | B8: 2 | D8: Number of payments N | E8: =B7*B8
A9: Yield Nominal Rate j^(m) | B9: 0.06 | D9: a = 1 + j/m | E9: =1+B9/B10
A10: Yield Compounding (m times/year) | B10: 2 | D10: Base price P0 | E10: =B13
D11: Python v2: optionally define a Curve sheet (pillars + zero rates) for curve pricing/scenarios.
A12: OUTPUTS
A13: Bond Price / PV (P) | B13: =SUM(E19:E218)
A14: Macaulay Duration (years) | B14: =IF(B13=0,"",SUMPRODUCT(B19:B218,E19:E218)/B13)
A15: Modified Duration (years) | B15: =IF(B14="","",B14/(1+B9/B10))
A16: Convexity (years^2) | B16: =IF(B13=0,"",SUMPRODUCT(B19:B218,(B19:B218+1/B10),E19:E218)/(B13*(1+B9/B10)^2))
A18: k | B18: Time t (yrs) | C18: Cash Flow | D18: Discount Factor | E18: PV
A19: =IF(1<= $E$8, 1, "") | B19: =IF(A19="","",A19/$B$8) | C19: =IF(A19="","",IF(A19<$E$8,$E$7,$E$7+$B$5)) | D19: =IF(A19="","",$E$9^(-$B$10*B19)) | E19: =IF(A19="","",C19*D19)
A20: =IF(2<= $E$8, 2, "") | B20: =IF(A20="","",A20/$B$8) | C20: =IF(A20="","",IF(A20<$E$8,$E$7,$E$7+$B$5)) | D20: =IF(A20="","",$E$9^(-$B$10*B20)) | E20: =IF(A20="","",C20*D20)
A21: =IF(3<= $E$8, 3, "") | B21: =IF(A21="","",A21/$B$8) | C21: =IF(A21="","",IF(A21<$E$8,$E$7,$E$7+$B$5)) | D21: =IF(A21="","",$E$9^(-$B$10*B21)) | E21: =IF(A21="","",C21*D21)
A22: =IF(4<= $E$8, 4, "") | B22: =IF(A22="","",A22/$B$8) | C22: =IF(A22="","",IF(A22<$E$8,$E$7,$E$7+$B$5)) | D22: =IF(A22="","",$E$9^(-$B$10*B22)) | E22: =IF(A22="","",C22*D22)
A23: =IF(5<= $E$8, 5, "") | B23: =IF(A23="","",A23/$B$8) | C23: =IF(A23="","",IF(A23<$E$8,$E$7,$E$7+$B$5)) | D23: =IF(A23="","",$E$9^(-$B$10*B23)) | E23: =IF(A23="","",C23*D23)
A24: =IF(6<= $E$8, 6, "") | B24: =IF(A24="","",A24/$B$8) | C24: =IF(A24="","",IF(A24<$E$8,$E$7,$E$7+$B$5)) | D24: =IF(A24="","",$E$9^(-$B$10*B24)) | E24: =IF(A24="","",C24*D24)
A25: =IF(7<= $E$8, 7, "") | B25: =IF(A25="","",A25/$B$8) | C25: =IF(A25="","",IF(A25<$E$8,$E$7,$E$7+$B$5)) | D25: =IF(A25="","",$E$9^(-$B$10*B25)) | E25: =IF(A25="","",C25*D25)
A26: =IF(8<= $E$8, 8, "") | B26: =IF(A26="","",A26/$B$8) | C26: =IF(A26="","",IF(A26<$E$8,$E$7,$E$7+$B$5)) | D26: =IF(A26="","",$E$9^(-$B$10*B26)) | E26: =IF(A26="","",C26*D26)
A27: =IF(9<= $E$8, 9, "") | B27: =IF(A27="","",A27/$B$8) | C27: =IF(A27="","",IF(A27<$E$8,$E$7,$E$7+$B$5)) | D27: =IF(A27="","",$E$9^(-$B$10*B27)) | E27: =IF(A27="","",C27*D27)
A28: =IF(10<= $E$8, 10, "") | B28: =IF(A28="","",A28/$B$8) | C28: =IF(A28="","",IF(A28<$E$8,$E$7,$E$7+$B$5)) | D28: =IF(A28="","",$E$9^(-$B$10*B28)) | E28: =IF(A28="","",C28*D28)
A29: =IF(11<= $E$8, 11, "") | B29: =IF(A29="","",A29/$B$8) | C29: =IF(A29="","",IF(A29<$E$8,$E$7,$E$7+$B$5)) | D29: =IF(A29="","",$E$9^(-$B$10*B29)) | E29: =IF(A29="","",C29*D29)
A30: =IF(12<= $E$8, 12, "") | B30: =IF(A30="","",A30/$B$8) | C30: =IF(A30="","",IF(A30<$E$8,$E$7,$E$7+$B$5)) | D30: =IF(A30="","",$E$9^(-$B$10*B30)) | E30: =IF(A30="","",C30*D30)
A31: =IF(13<= $E$8, 13, "") | B31: =IF(A31="","",A31/$B$8) | C31: =IF(A31="","",IF(A31<$E$8,$E$7,$E$7+$B$5)) | D31: =IF(A31="","",$E$9^(-$B$10*B31)) | E31: =IF(A31="","",C31*D31)
A32: =IF(14<= $E$8, 14, "") | B32: =IF(A32="","",A32/$B$8) | C32: =IF(A32="","",IF(A32<$E$8,$E$7,$E$7+$B$5)) | D32: =IF(A32="","",$E$9^(-$B$10*B32)) | E32: =IF(A32="","",C32*D32)
A33: =IF(15<= $E$8, 15, "") | B33: =IF(A33="","",A33/$B$8) | C33: =IF(A33="","",IF(A33<$E$8,$E$7,$E$7+$B$5)) | D33: =IF(A33="","",$E$9^(-$B$10*B33)) | E33: =IF(A33="","",C33*D33)
A34: =IF(16<= $E$8, 16, "") | B34: =IF(A34="","",A34/$B$8) | C34: =IF(A34="","",IF(A34<$E$8,$E$7,$E$7+$B$5)) | D34: =IF(A34="","",$E$9^(-$B$10*B34)) | E34: =IF(A34="","",C34*D34)
A35: =IF(17<= $E$8, 17, "") | B35: =IF(A35="","",A35/$B$8) | C35: =IF(A35="","",IF(A35<$E$8,$E$7,$E$7+$B$5)) | D35: =IF(A35="","",$E$9^(-$B$10*B35)) | E35: =IF(A35="","",C35*D35)
A36: =IF(18<= $E$8, 18, "") | B36: =IF(A36="","",A36/$B$8) | C36: =IF(A36="","",IF(A36<$E$8,$E$7,$E$7+$B$5)) | D36: =IF(A36="","",$E$9^(-$B$10*B36)) | E36: =IF(A36="","",C36*D36)
A37: =IF(19<= $E$8, 19, "") | B37: =IF(A37="","",A37/$B$8) | C37: =IF(A37="","",IF(A37<$E$8,$E$7,$E$7+$B$5)) | D37: =IF(A37="","",$E$9^(-$B$10*B37)) | E37: =IF(A37="","",C37*D37)
A38: =IF(20<= $E$8, 20, "") | B38: =IF(A38="","",A38/$B$8) | C38: =IF(A38="","",IF(A38<$E$8,$E$7,$E$7+$B$5)) | D38: =IF(A38="","",$E$9^(-$B$10*B38)) | E38: =IF(A38="","",C38*D38)
A39: =IF(21<= $E$8, 21, "") | B39: =IF(A39="","",A39/$B$8) | C39: =IF(A39="","",IF(A39<$E$8,$E$7,$E$7+$B$5)) | D39: =IF(A39="","",$E$9^(-$B$10*B39)) | E39: =IF(A39="","",C39*D39)
A40: =IF(22<= $E$8, 22, "") | B40: =IF(A40="","",A40/$B$8) | C40: =IF(A40="","",IF(A40<$E$8,$E$7,$E$7+$B$5)) | D40: =IF(A40="","",$E$9^(-$B$10*B40)) | E40: =IF(A40="","",C40*D40)
A41: =IF(23<= $E$8, 23, "") | B41: =IF(A41="","",A41/$B$8) | C41: =IF(A41="","",IF(A41<$E$8,$E$7,$E$7+$B$5)) | D41: =IF(A41="","",$E$9^(-$B$10*B41)) | E41: =IF(A41="","",C41*D41)
A42: =IF(24<= $E$8, 24, "") | B42: =IF(A42="","",A42/$B$8) | C42: =IF(A42="","",IF(A42<$E$8,$E$7,$E$7+$B$5)) | D42: =IF(A42="","",$E$9^(-$B$10*B42)) | E42: =IF(A42="","",C42*D42)
...

Sheet Help
A1: How to use this workbook
A3: 1) Inputs: fill Face Value, coupon rate, maturity (years), coupon frequency p, nominal yield j^(m), and compounding m. 2) Outputs update automatically: Price, Macaulay duration, modified duration, convexity. 3) Cash-Flow table shows time t (years), CF, discount factor (1+j/m)^(-m t), and PV. 4) Scenario table: install VBA module RunScenarios.bas then click the button to batch-run shocks. Notes: - Time is in years. j^(m) means nominal rate convertible m times per year. - If T*p is not an integer, adjust T or p so number of payments N is an integer. - To model irregular cash flows, you can overwrite the Cash Flow column values manually (and optionally Time). Price/duration/convexity will then reflect those edited cash flows (but the VBA scenario runner uses the standard bond schedule).

Sheet Curve
A1: Tenor (years) | B1: Zero rate j^(m) (decimal) | C1: Note
A2: 0.5 | B2: ='Bond Toolkit'!$B$9 | C2: Default: flat curve from template yield
A3: 1 | B3: ='Bond Toolkit'!$B$9 | C3: Default: flat curve from template yield
A4: 2 | B4: ='Bond Toolkit'!$B$9 | C4: Default: flat curve from template yield
A5: 5 | B5: ='Bond Toolkit'!$B$9 | C5: Default: flat curve from template yield
A6: 10 | B6: ='Bond Toolkit'!$B$9 | C6: Default: flat curve from template yield
A7: 20 | B7: ='Bond Toolkit'!$B$9 | C7: Default: flat curve from template yield
A8: 30 | B8: ='Bond Toolkit'!$B$9 | C8: Default: flat curve from template yield
